<?xml version="1.0"?>
<robot name="exia_ground" xmlns:xacro="http://www.ros.org/wiki/xacro">

  <xacro:arg name="config_path" default=""/>

  <xacro:arg name="lidar_horizontal_samples" default="360"/>
  <xacro:arg name="lidar_vertical_samples" default="16"/>
  <xacro:arg name="lidar_vertical_fov_min" default="-0.261799"/>
  <xacro:arg name="lidar_vertical_fov_max" default="0.261799"/>
  <xacro:arg name="lidar_range_min" default="1.0"/>
  <xacro:arg name="lidar_range_max" default="100.0"/>
  <xacro:arg name="lidar_update_rate" default="10"/>

  <link name="base_footprint"/>

  <link name="base_link">
    <visual>
      <origin xyz="0 0 0" rpy="0 0 0"/>
      <geometry>
        <box size="2.11 1.2 0.6"/>
      </geometry>
      <material name="blue">
        <color rgba="0.2 0.2 0.8 1"/>
      </material>
    </visual>

    <collision>
      <origin xyz="0 0 0" rpy="0 0 0"/>
      <geometry>
        <box size="2.11 1.2 0.6"/>
      </geometry>
    </collision>

    <inertial>
      <mass value="200.0"/>
      <origin xyz="0 0 0" rpy="0 0 0"/>
      <inertia ixx="30.0" ixy="0" ixz="0"
               iyy="80.2" iyz="0"
               izz="98.2"/>
    </inertial>
  </link>

  <joint name="base_joint" type="fixed">
    <parent link="base_footprint"/>
    <child link="base_link"/>
    <origin xyz="0 0 0.6" rpy="0 0 0"/>
  </joint>

  <link name="front_left_steer_link">
    <visual>
      <origin xyz="0 0 0" rpy="0 0 0"/>
      <geometry>
        <cylinder radius="0.05" length="0.08"/>
      </geometry>
      <material name="grey">
        <color rgba="0.5 0.5 0.5 1"/>
      </material>
    </visual>

    <collision>
      <origin xyz="0 0 0" rpy="0 0 0"/>
      <geometry>
        <cylinder radius="0.05" length="0.08"/>
      </geometry>
    </collision>

    <inertial>
      <mass value="2.0"/>
      <origin xyz="0 0 0" rpy="0 0 0"/>
      <inertia ixx="0.001" ixy="0" ixz="0"
               iyy="0.001" iyz="0"
               izz="0.001"/>
    </inertial>
  </link>

  <link name="front_right_steer_link">
    <visual>
      <origin xyz="0 0 0" rpy="0 0 0"/>
      <geometry>
        <cylinder radius="0.05" length="0.08"/>
      </geometry>
      <material name="grey">
        <color rgba="0.5 0.5 0.5 1"/>
      </material>
    </visual>

    <collision>
      <origin xyz="0 0 0" rpy="0 0 0"/>
      <geometry>
        <cylinder radius="0.05" length="0.08"/>
      </geometry>
    </collision>

    <inertial>
      <mass value="2.0"/>
      <origin xyz="0 0 0" rpy="0 0 0"/>
      <inertia ixx="0.001" ixy="0" ixz="0"
               iyy="0.001" iyz="0"
               izz="0.001"/>
    </inertial>
  </link>

  <joint name="front_left_steer_joint" type="revolute">
    <parent link="base_link"/>
    <child link="front_left_steer_link"/>
    <origin xyz="0.65 0.55 -0.3" rpy="0 0 0"/>
    <axis xyz="0 0 1"/>
    <limit lower="-0.6" upper="0.6" effort="2000.0" velocity="3.0"/>
    <dynamics damping="0.0" friction="0.0"/>
  </joint>

  <joint name="front_right_steer_joint" type="revolute">
    <parent link="base_link"/>
    <child link="front_right_steer_link"/>
    <origin xyz="0.65 -0.55 -0.3" rpy="0 0 0"/>
    <axis xyz="0 0 1"/>
    <limit lower="-0.6" upper="0.6" effort="2000.0" velocity="3.0"/>
    <dynamics damping="0.0" friction="0.0"/>
  </joint>

  <link name="front_left_wheel">
    <visual>
      <origin xyz="0 0 0" rpy="1.5708 0 0"/>
      <geometry>
        <cylinder radius="0.3" length="0.15"/>
      </geometry>
      <material name="black">
        <color rgba="0.1 0.1 0.1 1"/>
      </material>
    </visual>

    <collision>
      <origin xyz="0 0 0" rpy="1.5708 0 0"/>
      <geometry>
        <cylinder radius="0.3" length="0.15"/>
      </geometry>
    </collision>

    <inertial>
      <mass value="10.0"/>
      <origin xyz="0 0 0" rpy="1.5708 0 0"/>
      <inertia ixx="0.244" ixy="0" ixz="0"
               iyy="0.244" iyz="0"
               izz="0.45"/>
    </inertial>
  </link>

  <joint name="front_left_wheel_joint" type="continuous">
    <parent link="front_left_steer_link"/>
    <child link="front_left_wheel"/>
    <origin xyz="0 0 0" rpy="0 0 0"/>
    <axis xyz="0 1 0"/>
    <dynamics damping="0.1" friction="0.1"/>
  </joint>

  <link name="front_right_wheel">
    <visual>
      <origin xyz="0 0 0" rpy="1.5708 0 0"/>
      <geometry>
        <cylinder radius="0.3" length="0.15"/>
      </geometry>
      <material name="black">
        <color rgba="0.1 0.1 0.1 1"/>
      </material>
    </visual>

    <collision>
      <origin xyz="0 0 0" rpy="1.5708 0 0"/>
      <geometry>
        <cylinder radius="0.3" length="0.15"/>
      </geometry>
    </collision>

    <inertial>
      <mass value="10.0"/>
      <origin xyz="0 0 0" rpy="1.5708 0 0"/>
      <inertia ixx="0.244" ixy="0" ixz="0"
               iyy="0.244" iyz="0"
               izz="0.45"/>
    </inertial>
  </link>

  <joint name="front_right_wheel_joint" type="continuous">
    <parent link="front_right_steer_link"/>
    <child link="front_right_wheel"/>
    <origin xyz="0 0 0" rpy="0 0 0"/>
    <axis xyz="0 1 0"/>
    <dynamics damping="0.1" friction="0.1"/>
  </joint>

  <link name="rear_left_wheel">
    <visual>
      <origin xyz="0 0 0" rpy="1.5708 0 0"/>
      <geometry>
        <cylinder radius="0.3" length="0.15"/>
      </geometry>
      <material name="black">
        <color rgba="0.1 0.1 0.1 1"/>
      </material>
    </visual>

    <collision>
      <origin xyz="0 0 0" rpy="1.5708 0 0"/>
      <geometry>
        <cylinder radius="0.3" length="0.15"/>
      </geometry>
    </collision>

    <inertial>
      <mass value="10.0"/>
      <origin xyz="0 0 0" rpy="1.5708 0 0"/>
      <inertia ixx="0.244" ixy="0" ixz="0"
               iyy="0.244" iyz="0"
               izz="0.45"/>
    </inertial>
  </link>

  <joint name="rear_left_wheel_joint" type="continuous">
    <parent link="base_link"/>
    <child link="rear_left_wheel"/>
    <origin xyz="-0.65 0.55 -0.3" rpy="0 0 0"/>
    <axis xyz="0 1 0"/>
    <dynamics damping="0.01" friction="0.0"/>
  </joint>

  <link name="rear_right_wheel">
    <visual>
      <origin xyz="0 0 0" rpy="1.5708 0 0"/>
      <geometry>
        <cylinder radius="0.3" length="0.15"/>
      </geometry>
      <material name="black">
        <color rgba="0.1 0.1 0.1 1"/>
      </material>
    </visual>

    <collision>
      <origin xyz="0 0 0" rpy="1.5708 0 0"/>
      <geometry>
        <cylinder radius="0.3" length="0.15"/>
      </geometry>
    </collision>

    <inertial>
      <mass value="10.0"/>
      <origin xyz="0 0 0" rpy="1.5708 0 0"/>
      <inertia ixx="0.244" ixy="0" ixz="0"
               iyy="0.244" iyz="0"
               izz="0.45"/>
    </inertial>
  </link>

  <joint name="rear_right_wheel_joint" type="continuous">
    <parent link="base_link"/>
    <child link="rear_right_wheel"/>
    <origin xyz="-0.65 -0.55 -0.3" rpy="0 0 0"/>
    <axis xyz="0 1 0"/>
    <dynamics damping="0.01" friction="0.0"/>
  </joint>

  <link name="brake_actuator_link">
    <visual>
      <origin xyz="0 0 0" rpy="0 0 0"/>
      <geometry>
        <box size="0.15 0.2 0.1"/>
      </geometry>
      <material name="red">
        <color rgba="0.8 0.2 0.2 1"/>
      </material>
    </visual>

    <collision>
      <origin xyz="0 0 0" rpy="0 0 0"/>
      <geometry>
        <box size="0.15 0.2 0.1"/>
      </geometry>
    </collision>

    <inertial>
      <mass value="2.0"/>
      <origin xyz="0 0 0" rpy="0 0 0"/>
      <inertia ixx="0.001" ixy="0" ixz="0"
               iyy="0.001" iyz="0"
               izz="0.001"/>
    </inertial>
  </link>

  <joint name="brake_joint" type="revolute">
    <parent link="base_link"/>
    <child link="brake_actuator_link"/>
    <origin xyz="-0.5 0 -0.15" rpy="0 0 0"/>
    <axis xyz="0 1 0"/>
    <limit lower="0.0" upper="1.0" effort="2000.0" velocity="5.0"/>
    <dynamics damping="0.1" friction="0.0"/>
  </joint>

  <link name="imu_link">
    <visual>
      <origin xyz="0 0 0" rpy="0 0 0"/>
      <geometry>
        <box size="0.05 0.05 0.02"/>
      </geometry>
      <material name="green">
        <color rgba="0.2 0.8 0.2 1"/>
      </material>
    </visual>

    <collision>
      <origin xyz="0 0 0" rpy="0 0 0"/>
      <geometry>
        <box size="0.05 0.05 0.02"/>
      </geometry>
    </collision>

    <inertial>
      <mass value="0.05"/>
      <origin xyz="0 0 0" rpy="0 0 0"/>
      <inertia ixx="0.00001" ixy="0" ixz="0"
               iyy="0.00001" iyz="0"
               izz="0.00001"/>
    </inertial>
  </link>

  <joint name="imu_joint" type="fixed">
    <parent link="base_link"/>
    <child link="imu_link"/>
    <origin xyz="0 0 0.31" rpy="0 0 0"/>
  </joint>

  <link name="lidar_link">
    <visual>
      <origin xyz="0 0 0" rpy="0 0 0"/>
      <geometry>
        <cylinder radius="0.05" length="0.07"/>
      </geometry>
      <material name="dark_grey">
        <color rgba="0.2 0.2 0.2 1"/>
      </material>
    </visual>

    <collision>
      <origin xyz="0 0 0" rpy="0 0 0"/>
      <geometry>
        <cylinder radius="0.05" length="0.07"/>
      </geometry>
    </collision>

    <inertial>
      <mass value="0.83"/>
      <origin xyz="0 0 0" rpy="0 0 0"/>
      <inertia ixx="0.0005" ixy="0" ixz="0"
               iyy="0.0005" iyz="0"
               izz="0.001"/>
    </inertial>
  </link>

  <joint name="lidar_joint" type="fixed">
    <parent link="base_link"/>
    <child link="lidar_link"/>
    <origin xyz="0.3 0 0.42" rpy="0 0 0"/>
  </joint>

  <link name="camera_link">
    <visual>
      <origin xyz="0 0 0" rpy="0 0 0"/>
      <geometry>
        <box size="0.09 0.025 0.025"/>
      </geometry>
      <material name="dark_grey">
        <color rgba="0.2 0.2 0.2 1"/>
      </material>
    </visual>
    <collision>
      <origin xyz="0 0 0" rpy="0 0 0"/>
      <geometry>
        <box size="0.09 0.025 0.025"/>
      </geometry>
    </collision>
    <inertial>
      <mass value="0.072"/>
      <origin xyz="0 0 0" rpy="0 0 0"/>
      <inertia ixx="0.00001" ixy="0" ixz="0"
               iyy="0.00001" iyz="0"
               izz="0.00001"/>
    </inertial>
  </link>

  <joint name="camera_joint" type="fixed">
    <parent link="base_link"/>
    <child link="camera_link"/>
    <origin xyz="0.4 0 0.52" rpy="0 0 0"/>
  </joint>

  <link name="camera_depth_optical_frame"/>

  <joint name="camera_optical_joint" type="fixed">
    <parent link="camera_link"/>
    <child link="camera_depth_optical_frame"/>
    <origin xyz="0 0 0" rpy="-1.5708 0 -1.5708"/>
  </joint>

  <link name="gps_link">
    <visual>
      <origin xyz="0 0 0" rpy="0 0 0"/>
      <geometry>
        <box size="0.06 0.06 0.02"/>
      </geometry>
      <material name="white">
        <color rgba="0.9 0.9 0.9 1"/>
      </material>
    </visual>

    <collision>
      <origin xyz="0 0 0" rpy="0 0 0"/>
      <geometry>
        <box size="0.06 0.06 0.02"/>
      </geometry>
    </collision>

    <inertial>
      <mass value="0.1"/>
      <origin xyz="0 0 0" rpy="0 0 0"/>
      <inertia ixx="0.00001" ixy="0" ixz="0"
               iyy="0.00001" iyz="0"
               izz="0.00001"/>
    </inertial>
  </link>

  <joint name="gps_joint" type="fixed">
    <parent link="base_link"/>
    <child link="gps_link"/>
    <origin xyz="0 0 0.35" rpy="0 0 0"/>
  </joint>

  <gazebo reference="front_left_wheel">
    <collision>
      <surface>
        <friction>
          <ode>
            <mu>1.5</mu>
            <mu2>1.5</mu2>
          </ode>
        </friction>
      </surface>
    </collision>
  </gazebo>

  <gazebo reference="front_right_wheel">
    <collision>
      <surface>
        <friction>
          <ode>
            <mu>1.5</mu>
            <mu2>1.5</mu2>
          </ode>
        </friction>
      </surface>
    </collision>
  </gazebo>

  <gazebo reference="rear_left_wheel">
    <collision>
      <surface>
        <friction>
          <ode>
            <mu>1.5</mu>
            <mu2>1.5</mu2>
          </ode>
        </friction>
      </surface>
    </collision>
  </gazebo>

  <gazebo reference="rear_right_wheel">
    <collision>
      <surface>
        <friction>
          <ode>
            <mu>1.5</mu>
            <mu2>1.5</mu2>
          </ode>
        </friction>
      </surface>
    </collision>
  </gazebo>

  <gazebo reference="imu_link">
    <sensor name="imu_sensor" type="imu">
      <always_on>true</always_on>
      <update_rate>200</update_rate>
      <topic>imu</topic>
      <imu>
        <angular_velocity>
          <x><noise type="gaussian"><mean>0.0</mean><stddev>0.0002</stddev></noise></x>
          <y><noise type="gaussian"><mean>0.0</mean><stddev>0.0002</stddev></noise></y>
          <z><noise type="gaussian"><mean>0.0</mean><stddev>0.0002</stddev></noise></z>
        </angular_velocity>
        <linear_acceleration>
          <x><noise type="gaussian"><mean>0.0</mean><stddev>0.017</stddev></noise></x>
          <y><noise type="gaussian"><mean>0.0</mean><stddev>0.017</stddev></noise></y>
          <z><noise type="gaussian"><mean>0.0</mean><stddev>0.017</stddev></noise></z>
        </linear_acceleration>
      </imu>
    </sensor>
  </gazebo>

  <gazebo reference="lidar_link">
    <sensor name="lidar_3d" type="gpu_lidar">
      <always_on>true</always_on>
      <update_rate>$(arg lidar_update_rate)</update_rate>
      <topic>lidar_3d</topic>
      <gz_frame_id>lidar_link</gz_frame_id>
      <lidar>
        <scan>
          <horizontal>
            <samples>$(arg lidar_horizontal_samples)</samples>
            <resolution>1</resolution>
            <min_angle>-3.14159</min_angle>
            <max_angle>3.14159</max_angle>
          </horizontal>
          <vertical>
            <samples>$(arg lidar_vertical_samples)</samples>
            <resolution>1</resolution>
            <min_angle>$(arg lidar_vertical_fov_min)</min_angle>
            <max_angle>$(arg lidar_vertical_fov_max)</max_angle>
          </vertical>
        </scan>
        <range>
          <min>$(arg lidar_range_min)</min>
          <max>$(arg lidar_range_max)</max>
        </range>
        <noise>
          <type>gaussian</type>
          <mean>0.0</mean>
          <stddev>0.01</stddev>
        </noise>
      </lidar>
      <visualize>true</visualize>
    </sensor>
  </gazebo>

  <gazebo reference="camera_link">
    <sensor name="depth_camera" type="rgbd_camera">
      <always_on>true</always_on>
      <update_rate>15</update_rate>
      <topic>depth_camera</topic>
      <gz_frame_id>camera_depth_optical_frame</gz_frame_id>
      <camera>
        <horizontal_fov>1.7627</horizontal_fov>
        <image>
          <width>640</width>
          <height>480</height>
        </image>
        <clip>
          <near>0.2</near>
          <far>20.0</far>
        </clip>
        <depth_camera>
          <clip>
            <near>0.2</near>
            <far>20.0</far>
          </clip>
        </depth_camera>
        <noise>
          <type>gaussian</type>
          <mean>0.0</mean>
          <stddev>0.005</stddev>
        </noise>
      </camera>
      <visualize>true</visualize>
    </sensor>
  </gazebo>

  <gazebo reference="gps_link">
    <sensor name="navsat_sensor" type="navsat">
      <always_on>true</always_on>
      <update_rate>10</update_rate>
      <topic>navsat</topic>
      <gz_frame_id>gps_link</gz_frame_id>
      <navsat>
        <position_sensing>
          <horizontal>
            <noise type="gaussian">
              <mean>0.0</mean>
              <stddev>0.5</stddev>
            </noise>
          </horizontal>
          <vertical>
            <noise type="gaussian">
              <mean>0.0</mean>
              <stddev>1.0</stddev>
            </noise>
          </vertical>
        </position_sensing>
        <velocity_sensing>
          <horizontal>
            <noise type="gaussian">
              <mean>0.0</mean>
              <stddev>0.1</stddev>
            </noise>
          </horizontal>
          <vertical>
            <noise type="gaussian">
              <mean>0.0</mean>
              <stddev>0.1</stddev>
            </noise>
          </vertical>
        </velocity_sensing>
      </navsat>
    </sensor>
  </gazebo>

  <ros2_control name="GazeboSimSystem" type="system">
    <hardware>
      <plugin>gz_ros2_control/GazeboSimSystem</plugin>
    </hardware>

    <joint name="front_left_steer_joint">
      <command_interface name="position"/>
      <state_interface name="position"/>
      <state_interface name="velocity"/>
    </joint>
    <joint name="front_right_steer_joint">
      <command_interface name="position"/>
      <state_interface name="position"/>
      <state_interface name="velocity"/>
    </joint>

    <joint name="rear_left_wheel_joint">
      <command_interface name="velocity"/>
      <state_interface name="position"/>
      <state_interface name="velocity"/>
    </joint>
    <joint name="rear_right_wheel_joint">
      <command_interface name="velocity"/>
      <state_interface name="position"/>
      <state_interface name="velocity"/>
    </joint>

    <joint name="brake_joint">
      <command_interface name="position"/>
      <state_interface name="position"/>
      <state_interface name="velocity"/>
    </joint>
  </ros2_control>

  <gazebo>
    <plugin filename="gz_ros2_control-system" name="gz_ros2_control::GazeboSimROS2ControlPlugin">
      <robot_param>robot_description</robot_param>
      <robot_param_node>robot_state_publisher</robot_param_node>
      <parameters>$(arg config_path)</parameters>
    </plugin>
  </gazebo>

</robot>
